Waiting until tomorrow's 8:20 AM...
    [chart_visualization.py, RLTD] Created new log file: `SPY_2M.log`
    [chart_visualization.py, UCP] Waiting for live candles...
[INFO] Running initial_setup and main_loop at 2025-07-08 09:20:07
We have logged in as TradeMaster#8429

[DATA_AQUISITION] 'is_market_open()' DATA:
{'afterHours': False, 'currencies': {'crypto': 'open', 'fx': 'open'}, 'earlyHours': True, 'exchanges': {'nasdaq': 'extended-hours', 'nyse': 'extended-hours', 'otc': 'extended-hours'}, 'indicesGroups': {'s_and_p': 'open', 'societe_generale': 'open', 'msci': 'closed', 'ftse_russell': 'closed', 'mstar': 'open', 'mstarc': 'open', 'cccy': 'open', 'cgi': 'open', 'nasdaq': 'open', 'dow_jones': 'closed'}, 'market': 'extended-hours', 'serverTime': '2025-07-08T09:20:13-04:00'}

[load_recent_15m_candles] Loaded 118 rows covering 5 days, offset = 33209
[load_recent_15m_candles] Loaded 118 rows covering 5 days, offset = 33209
The market is about to open. Waiting 590 seconds...
[setup_global_chart] setting global root and canvas
Exception in thread chart_root:
Traceback (most recent call last):
  File "C:\Users\HNI\AppData\Local\Programs\Python\Python39\lib\threading.py", line 954, in _bootstrap_inner
    [chart_visualization.py, UCP] Waiting for live candles...
    self.run()
  File "C:\Users\HNI\AppData\Local\Programs\Python\Python39\lib\threading.py", line 892, in run
    self._target(*self._args, **self._kwargs)
  File "C:\Users\HNI\OneDrive\Desktop\Coding\Trading programs\Flag-Zone-Bot\chart_visualization.py", line 365, in plot_candles_and_boxes
    tk.mainloop()
  File "C:\Users\HNI\AppData\Local\Programs\Python\Python39\lib\tkinter\__init__.py", line 603, in mainloop
    _get_default_root('run the main loop').tk.mainloop(n)
RuntimeError: Calling Tcl from different apartment
Exception in thread Thread-55:
Traceback (most recent call last):
  File "C:\Users\HNI\AppData\Local\Programs\Python\Python39\lib\threading.py", line 954, in _bootstrap_inner
    self.run()
  File "C:\Users\HNI\AppData\Local\Programs\Python\Python39\lib\threading.py", line 892, in run
    self._target(*self._args, **self._kwargs)
  File "C:\Users\HNI\OneDrive\Desktop\Coding\Trading programs\Flag-Zone-Bot\chart_visualization.py", line 86, in update_chart_periodically
    button_2_min.config(state=tk.DISABLED)
  File "C:\Users\HNI\AppData\Local\Programs\Python\Python39\lib\tkinter\__init__.py", line 1646, in configure
    return self._configure('configure', cnf, kw)
  File "C:\Users\HNI\AppData\Local\Programs\Python\Python39\lib\tkinter\__init__.py", line 1636, in _configure
    self.tk.call(_flatten((self._w, cmd)) + self._options(cnf))
RuntimeError: main thread is not in main loop
Exception in thread Thread-42:
Traceback (most recent call last):
  File "C:\Users\HNI\AppData\Local\Programs\Python\Python39\lib\threading.py", line 954, in _bootstrap_inner
    self.run()
  File "C:\Users\HNI\AppData\Local\Programs\Python\Python39\lib\threading.py", line 892, in run
    self._target(*self._args, **self._kwargs)
  File "C:\Users\HNI\OneDrive\Desktop\Coding\Trading programs\Flag-Zone-Bot\chart_visualization.py", line 86, in update_chart_periodically
    button_2_min.config(state=tk.DISABLED)
  File "C:\Users\HNI\AppData\Local\Programs\Python\Python39\lib\tkinter\__init__.py", line 1646, in configure
    return self._configure('configure', cnf, kw)
  File "C:\Users\HNI\AppData\Local\Programs\Python\Python39\lib\tkinter\__init__.py", line 1636, in _configure
    self.tk.call(_flatten((self._w, cmd)) + self._options(cnf))
RuntimeError: main thread is not in main loop